<?xml version="1.0" ?>
<robot name="drawer">
  <!-- Cabinet -->
  <link name="cabinet_link">
    <contact>
      <friction_anchor/>
      <lateral_friction value="2.0"/> <!--  lateral friction for stability -->
      <rolling_friction value="2.01"/> <!--  rolling friction for stability -->
    </contact>
    <inertial>
       <origin rpy="0 0 0" xyz="0 0 0"/>
       <mass value="10.1"/>
            <inertia ixx="0.0" ixy="0.0" ixz="0.0" iyy="0.0" iyz="0.0" izz="0.0" />
    </inertial>
    <visual>
      <geometry>
        <mesh filename="./cabinet/cabinet_convex.obj" scale="1 0.95 1"/>
      </geometry>
    </visual>
    <collision>
      <geometry>
    	 	<mesh filename="./cabinet/cabinet_convex.obj" scale="1 0.95 1"/>
      </geometry>
    </collision>
  </link>


  <!-- Drawer  -->
  <link name="drawer_link">
    <contact>
      <friction_anchor/>
      <lateral_friction value="25.1"/> <!--  lateral friction 6.1 for non vhacd -->
      <rolling_friction value="30.6"/> <!--  rolling friction 7.6 -->
    </contact>
    <inertial>
       <origin rpy="0 0 0" xyz="0 0 -0.1"/>
       <mass value="0.1"/>
            <inertia ixx="0.0" ixy="0.0" ixz="0.0" iyy="0.0" iyz="0.0" izz="0.0" />
    </inertial>
    <visual>
      <geometry>
        <mesh filename="./drawer/drawer_convex.obj" scale="0.8 0.8 0.6"/>
      </geometry>
    </visual>
    <collision>
      <geometry>
    	 	<mesh filename="./drawer/drawer_convex.obj" scale="0.8 0.8 0.6"/>
      </geometry>
    </collision>
  </link>
 
  <joint name="drawer_joint" type="prismatic">
    <parent link="cabinet_link"/>
    <child link="drawer_link"/>
    <origin xyz="0 0 0" rpy="0 0 0"/>
    <axis xyz="-1 0 0"/>
        <dynamics damping="0" friction="0" />
        <limit lower="0" upper="0.13" effort="100" velocity="5"/>
  </joint>


    <joint name="handle_joint" type="fixed">
    <parent link="drawer_link"/>
    <child link="handle"/>
    <origin rpy="0 0 0" xyz="-0.195 0.0 -0.028"/>
  </joint>
  <link name="handle">
    <inertial>
       <origin rpy="0 0 0" xyz="0 0 -0.1"/>
       <mass value="0.0000001"/>
            <inertia ixx="0.0" ixy="0.0" ixz="0.0" iyy="0.0" iyz="0.0" izz="0.0" />
    </inertial>
    <visual>
      <origin rpy="0 0 0" xyz="0 0.0 0"/>
      <geometry>
        <sphere radius="0.01"/>
      </geometry>
    <material name="green">
        <color rgba="0.0 1 0.0 1.0"/>
    </material>

    </visual>
  </link>

    <joint name="drawer_inside_joint" type="fixed">
    <parent link="drawer_link"/>
    <child link="drawer_bottom"/>
    <origin rpy="0 0 0" xyz="-0.02 0.0 -0.025"/>
  </joint>
  <link name="drawer_bottom">
    <inertial>
       <origin rpy="0 0 0" xyz="0 0 -0.1"/>
       <mass value="0.0000001"/>
            <inertia ixx="0.0" ixy="0.0" ixz="0.0" iyy="0.0" iyz="0.0" izz="0.0" />
    </inertial>
    <visual>
      <origin rpy="0 0 0" xyz="0 0.0 0"/>
      <geometry>
        <sphere radius="0.000001"/>
      </geometry>
    <material name="blue">
        <color rgba="1.0 0 1.0 0.0"/>
    </material>
    </visual>
  </link>
  
</robot>


